Workbook

Sheet 00_Revision_cover
A1: BAAY PROJECTS LIMITED · RC 1526224
A2: Sales and customers — revised
A3: REVISED · 8 October 2026 · original sheets retained so their formulas still work
A5: The original sheets are unchanged. The revision is the two sheets added at the front: this cover, and IFRS15_recognition.
A6: Turnover remains the Sales_Ledger: 859 lines, ₦2,584,814,000 for 2023 to 2025. Nothing was added from the Exceptions tab, and nothing was scaled.
A7: IFRS15_recognition applies the revenue policy to each subscription and to uncontracted sales-ledger lines. Revenue, the receivable and the deferred income on that sheet are the figures in the revised financial statements.
A8: Land marked bought or closed starts from the contract value. The receivable is capped at the client-register balance, and revenue on the sheet is reduced by the same amount. That reduction is ₦515,131,000 across 2023 to 2025. If the register is incomplete, revenue and receivables are both understated. Housing is recognised only on evidenced handover. Other collections are deferred income.
A9: A receivable is only the unpaid balance of a recognised contract, and not above the register balance. Unpaid balances on contracts still deferred are not receivables. They are a pipeline, disclosed in the financial statements.
A10: Exclusions (co-ownership, service income, credit memos) stay off turnover. Co-ownership is a liability in the revised statements. Credit memos are non-cash and are not posted.
A11: Client-register rows dated 2026 are outside this revision.

Sheet IFRS15_recognition
A1: Sub ref | B1: Customer | C1: Product | D1: Project | E1: Status | F1: Contract value | G1: Policy | H1: Collections 2023 | I1: Collections 2024 | J1: Collections 2025 | K1: Revenue 2023 | L1: Revenue 2024 | M1: Revenue 2025 | N1: Receivable at 31 Dec 2025 | O1: Deferred income at 31 Dec 2025
A2: SB0001 | B2: Mr Meshack Osagie | C2: Housing | D2: Pacific Court | E2: PAID | F2: 10500000 | G2: Housing not yet handed over — receipts held as deferred income (contract liability) | H2: 0 | I2: 0 | J2: 0 | K2: 0 | L2: 0 | M2: 0 | N2: 0 | O2: 0
A3: SB0002 | B3: Temidayo Oniosun | C3: Housing | D3: Pacific Court | E3: PAID | F3: 52200000 | G3: Housing not yet handed over — receipts held as deferred income (contract liability) | H3: 0 | I3: 0 | J3: 0 | K3: 0 | L3: 0 | M3: 0 | N3: 0 | O3: 0
A4: SB0003 | B4: Mrs Agbaje | C4: Housing | D4: Pacific Court | E4: PAID | F4: 63000000 | G4: Housing not yet handed over — receipts held as deferred income (contract liability) | H4: 0 | I4: 0 | J4: 0 | K4: 0 | L4: 0 | M4: 0 | N4: 0 | O4: 0
A5: SB0004 | B5: Mrs Kate | C5: Housing | D5: Pacific Court | E5: REFUND | F5: 40000000 | G5: Housing not yet handed over — receipts held as deferred income (contract liability) | H5: 0 | I5: 0 | J5: 0 | K5: 0 | L5: 0 | M5: 0 | N5: 0 | O5: 0
A6: SB0005 | B6: Mrs Mo | C6: Housing | D6: Pacific Court | E6: PAID | F6: 47000000 | G6: Housing not yet handed over — receipts held as deferred income (contract liability) | H6: 0 | I6: 0 | J6: 0 | K6: 0 | L6: 0 | M6: 0 | N6: 0 | O6: 0
A7: SB0006 | B7: Mrs Ero | C7: Housing | D7: Pacific Court | E7: PAID | F7: 600000000 | G7: Housing not yet handed over — receipts held as deferred income (contract liability) | H7: 0 | I7: 0 | J7: 0 | K7: 0 | L7: 0 | M7: 0 | N7: 0 | O7: 0
A8: SB0007 | B8: Mr Rasaq Roqeeb | C8: Land | D8: Green City Phase 1 (Lantaba, Ketu-Epe) | E8: BOUGHT | F8: 3900000 | G8: Land control transferred (allocated / bought). Revenue at contract value | H8: 500000 | I8: 1150000 | J8: 0 | K8: 500000 | L8: 0 | M8: 0 | N8: 0 | O8: 1150000
A9: SB0008 | B9: OLAIYA SUNDAY TEMITOPE | C9: Land | D9: Green City Phase 1 (Lantaba, Ketu-Epe) | E9: BOUGHT | F9: 1500000 | G9: Land control transferred (allocated / bought). Revenue at contract value | H9: 0 | I9: 475000 | J9: 0 | K9: 0 | L9: 0 | M9: 0 | N9: 0 | O9: 475000
A10: SB0009 | B10: MOSHOOD TIJANI | C10: Land | D10: Green City Phase 1 (Lantaba, Ketu-Epe) | E10: BOUGHT | F10: 1500000 | G10: Land control transferred (allocated / bought). Revenue at contract value | H10: 1000000 | I10: 400000 | J10: 0 | K10: 1100000 | L10: 0 | M10: 0 | N10: 0 | O10: 300000
A11: SB0010 | B11: PROF OLUGBENGA AKINADE/MRS ARAWOMO OMOLOLA | C11: Land | D11: Green City Phase 1 (Lantaba, Ketu-Epe) | E11: BOUGHT | F11: 3600000 | G11: Land control transferred (allocated / bought). Revenue at contract value | H11: 0 | I11: 0 | J11: 0 | K11: 0 | L11: 0 | M11: 0 | N11: 0 | O11: 0
A12: SB0011 | B12: MR Damilare Ositade Owolabi | C12: Land | D12: Green City Phase 1 (Lantaba, Ketu-Epe) | E12: BOUGHT | F12: 1500000 | G12: Land control transferred (allocated / bought). Revenue at contract value | H12: 1500000 | I12: 135000 | J12: 0 | K12: 1500000 | L12: 0 | M12: 0 | N12: 0 | O12: 135000
A13: SB0012 | B13: Mr Tobi Adesina | C13: Land | D13: Green City Phase 1 (Lantaba, Ketu-Epe) | E13: INCENTIVES | F13: 1500000 | G13: Land subscription still paying / refund / no completed status — receipts deferred | H13: 0 | I13: 0 | J13: 0 | K13: 0 | L13: 0 | M13: 0 | N13: 0 | O13: 0
... A215: SB0214 | B215: Mrs and Mr Bidemi | C215: Housing | D215: Pacific Court | E215: ALMOST BOUGHT | F215: 0 | G215: Housing not yet handed over — receipts held as deferred income (contract liability) | H215: 0 | I215: 0 | J215: 0 | K215: 0 | L215: 0 | M215: 0 | N215: 0 | O215: 0
A216: UN-0001 | B216: Mr Olasupo Oladimeji | C216: Land | D216: Land (estate not stated in source) | F216: 0 | G216: Plot receipt with no open subscription — recognised in the year of receipt (turnover-register basis) | H216: 894000 | I216: 0 | J216: 0 | K216: 894000 | L216: 0 | M216: 0 | N216: 0 | O216: 0
A217: UN-0002 | B217: Mr Olasupo Oladimeji Muritala | C217: Land | D217: Land (estate not stated in source) | F217: 0 | G217: Plot receipt with no open subscription — recognised in the year of receipt (turnover-register basis) | H217: 2000000 | I217: 0 | J217: 0 | K217: 2000000 | L217: 0 | M217: 0 | N217: 0 | O217: 0
A218: UN-0003 | B218: Miss Oji Blessing Mary | C218: Land | D218: Land: corner piece premium | F218: 0 | G218: Plot receipt with no open subscription — recognised in the year of receipt (turnover-register basis) | H218: 0 | I218: 135000 | J218: 0 | K218: 0 | L218: 135000 | M218: 0 | N218: 0 | O218: 0
A219: UN-0004 | B219: Mrs Yohanna Paulina | C219: Land | D219: Land (estate not stated in source) | F219: 0 | G219: Plot receipt with no open subscription — recognised in the year of receipt (turnover-register basis) | H219: 300000 | I219: 0 | J219: 0 | K219: 300000 | L219: 0 | M219: 0 | N219: 0 | O219: 0
A220: UN-0005 | B220: Mr Taiwo John Adeleye | C220: Land | D220: Land (estate not stated in source) | F220: 0 | G220: Plot receipt with no open subscription — recognised in the year of receipt (turnover-register basis) | H220: 0 | I220: 0 | J220: 45000 | K220: 0 | L220: 0 | M220: 45000 | N220: 0 | O220: 0
A221: UN-0006 | B221: Mr Ogbu Pius Ejaka | C221: Land | D221: Land (estate not stated in source) | F221: 0 | G221: Plot receipt with no open subscription — recognised in the year of receipt (turnover-register basis) | H221: 1500000 | I221: 0 | J221: 6500000 | K221: 1500000 | L221: 0 | M221: 6500000 | N221: 0 | O221: 0
A222: UN-0007 | B222: Mr Ogbu Pius Ejaka | C222: Land | D222: Land: corner piece premium | F222: 0 | G222: Plot receipt with no open subscription — recognised in the year of receipt (turnover-register basis) | H222: 0 | I222: 135000 | J222: 0 | K222: 0 | L222: 135000 | M222: 0 | N222: 0 | O222: 0
A223: UN-0008 | B223: Mr & Mrs Adebayo Dada | C223: Land | D223: Land (estate not stated in source) | F223: 0 | G223: Plot receipt with no open subscription — recognised in the year of receipt (turnover-register basis) | H223: 3000000 | I223: 0 | J223: 0 | K223: 3000000 | L223: 0 | M223: 0 | N223: 0 | O223: 0
A224: UN-0009 | B224: Mr & Mrs Adebayo Dada | C224: Land | D224: Land: corner piece premium | F224: 0 | G224: Plot receipt with no open subscription — recognised in the year of receipt (turnover-register basis) | H224: 0 | I224: 135000 | J224: 0 | K224: 0 | L224: 135000 | M224: 0 | N224: 0 | O224: 0
A225: UN-0010 | B225: Mr Adebayo Dada | C225: Land | D225: Land (estate not stated in source) | F225: 0 | G225: Plot receipt with no open subscription — recognised in the year of receipt (turnover-register basis) | H225: 1300000 | I225: 0 | J225: 0 | K225: 1300000 | L225: 0 | M225: 0 | N225: 0 | O225: 0
A226: UN-0011 | B226: Mr Edun Ayobami Simeon | C226: Land | D226: Land: corner piece premium | F226: 0 | G226: Plot receipt with no open subscription — recognised in the year of receipt (turnover-register basis) | H226: 0 | I226: 135000 | J226: 0 | K226: 0 | L226: 135000 | M226: 0 | N226: 0 | O226: 0
A227: UN-0012 | B227: Mr Adebanjo Isaac | C227: Land | D227: Land (estate not stated in source) | F227: 0 | G227: Plot receipt with no open subscription — recognised in the year of receipt (turnover-register basis) | H227: 250000 | I227: 0 | J227: 0 | K227: 250000 | L227: 0 | M227: 0 | N227: 0 | O227: 0
... A362: UN-0147 | B362: Mr Opeodu Ayodele & Mr Daisi Omokoya | C362: Housing | D362: Gorge View Court (GVC Gbagada) | F362: 0 | G362: Housing receipt with no handover evidence — deferred income | H362: 0 | I362: 0 | J362: 250000000 | K362: 0 | L362: 0 | M362: 0 | N362: 0 | O362: 250000000
A363: Total | F363: 4016366740 | H363: 125620000 | I363: 594080600 | J363: 1865113400 | K363: 84117680 | L363: 350864060 | M363: 940893400 | N363: 14900000 | O363: 1223838860

Sheet Summary
A1: BAAY Projects Limited: sales and customer summary for the auditor, 2022 to 2025
A2: Prepared 2 October 2026 from the company Google Drive (not Xero). All figures are cash receipts per company records, in Naira. Every number below is a formula on the detail tabs.
A4: 1. Sales receipts by product line and year (Sales_Ledger)
A5: 2022 shows nil: no transaction-level receipts for 2022 exist on the Drive. Construction shows nil: no construction-contract receipts were found for 2022 to 2025.
A6: Product line | B6: 2022 | C6: 2023 | D6: 2024 | E6: 2025 | F6: Total 2022-2025
A7: Land: plot price / instalments | B7: =SUMIFS(Sales_Ledger!$J$5:$J$863,Sales_Ledger!$E$5:$E$863,"Land",Sales_Ledger!$D$5:$D$863,2022,Sales_Ledger!$F$5:$F$863,"Plot / unit price") | C7: =SUMIFS(Sales_Ledger!$J$5:$J$863,Sales_Ledger!$E$5:$E$863,"Land",Sales_Ledger!$D$5:$D$863,2023,Sales_Ledger!$F$5:$F$863,"Plot / unit price") | D7: =SUMIFS(Sales_Ledger!$J$5:$J$863,Sales_Ledger!$E$5:$E$863,"Land",Sales_Ledger!$D$5:$D$863,2024,Sales_Ledger!$F$5:$F$863,"Plot / unit price") | E7: =SUMIFS(Sales_Ledger!$J$5:$J$863,Sales_Ledger!$E$5:$E$863,"Land",Sales_Ledger!$D$5:$D$863,2025,Sales_Ledger!$F$5:$F$863,"Plot / unit price") | F7: =SUM(B7:E7)
A8: Land: ancillary charges (corner piece, documentation, development) | B8: =SUMIFS(Sales_Ledger!$J$5:$J$863,Sales_Ledger!$E$5:$E$863,"Land",Sales_Ledger!$D$5:$D$863,2022,Sales_Ledger!$F$5:$F$863,"Ancillary charge") | C8: =SUMIFS(Sales_Ledger!$J$5:$J$863,Sales_Ledger!$E$5:$E$863,"Land",Sales_Ledger!$D$5:$D$863,2023,Sales_Ledger!$F$5:$F$863,"Ancillary charge") | D8: =SUMIFS(Sales_Ledger!$J$5:$J$863,Sales_Ledger!$E$5:$E$863,"Land",Sales_Ledger!$D$5:$D$863,2024,Sales_Ledger!$F$5:$F$863,"Ancillary charge") | E8: =SUMIFS(Sales_Ledger!$J$5:$J$863,Sales_Ledger!$E$5:$E$863,"Land",Sales_Ledger!$D$5:$D$863,2025,Sales_Ledger!$F$5:$F$863,"Ancillary charge") | F8: =SUM(B8:E8)
A9: Housing: unit price / instalments | B9: =SUMIFS(Sales_Ledger!$J$5:$J$863,Sales_Ledger!$E$5:$E$863,"Housing",Sales_Ledger!$D$5:$D$863,2022,Sales_Ledger!$F$5:$F$863,"Plot / unit price") | C9: =SUMIFS(Sales_Ledger!$J$5:$J$863,Sales_Ledger!$E$5:$E$863,"Housing",Sales_Ledger!$D$5:$D$863,2023,Sales_Ledger!$F$5:$F$863,"Plot / unit price") | D9: =SUMIFS(Sales_Ledger!$J$5:$J$863,Sales_Ledger!$E$5:$E$863,"Housing",Sales_Ledger!$D$5:$D$863,2024,Sales_Ledger!$F$5:$F$863,"Plot / unit price") | E9: =SUMIFS(Sales_Ledger!$J$5:$J$863,Sales_Ledger!$E$5:$E$863,"Housing",Sales_Ledger!$D$5:$D$863,2025,Sales_Ledger!$F$5:$F$863,"Plot / unit price") | F9: =SUM(B9:E9)
A10: Construction | B10: =SUMIFS(Sales_Ledger!$J$5:$J$863,Sales_Ledger!$E$5:$E$863,"Construction",Sales_Ledger!$D$5:$D$863,2022) | C10: =SUMIFS(Sales_Ledger!$J$5:$J$863,Sales_Ledger!$E$5:$E$863,"Construction",Sales_Ledger!$D$5:$D$863,2023) | D10: =SUMIFS(Sales_Ledger!$J$5:$J$863,Sales_Ledger!$E$5:$E$863,"Construction",Sales_Ledger!$D$5:$D$863,2024) | E10: =SUMIFS(Sales_Ledger!$J$5:$J$863,Sales_Ledger!$E$5:$E$863,"Construction",Sales_Ledger!$D$5:$D$863,2025) | F10: =SUM(B10:E10)
A11: Total sales receipts | B11: =SUM(B7:B10) | C11: =SUM(C7:C10) | D11: =SUM(D7:D10) | E11: =SUM(E7:E10) | F11: =SUM(F7:F10)
A12: Check: agrees to Sales_Ledger total (should be 0) | F12: =F11-SUM(Sales_Ledger!$J$5:$J$863)
A14: 2. How each year's receipts were sourced
A15: The basis tells the auditor how much reliance the list can bear before agreeing it to bank statements.
A16: Population basis | B16: 2022 | C16: 2023 | D16: 2024 | E16: 2025 | F16: Total
A17: Monthly turnover register (Dec 2023 to Dec 2024) | B17: =SUMIFS(Sales_Ledger!$J$5:$J$863,Sales_Ledger!$L$5:$L$863,"Primary: monthly turnover register",Sales_Ledger!$D$5:$D$863,2022) | C17: =SUMIFS(Sales_Ledger!$J$5:$J$863,Sales_Ledger!$L$5:$L$863,"Primary: monthly turnover register",Sales_Ledger!$D$5:$D$863,2023) | D17: =SUMIFS(Sales_Ledger!$J$5:$J$863,Sales_Ledger!$L$5:$L$863,"Primary: monthly turnover register",Sales_Ledger!$D$5:$D$863,2024) | E17: =SUMIFS(Sales_Ledger!$J$5:$J$863,Sales_Ledger!$L$5:$L$863,"Primary: monthly turnover register",Sales_Ledger!$D$5:$D$863,2025) | F17: =SUM(B17:E17)
A18: Turnover schedule, Green City Ph1/Ph2 (Jan to Nov 2023) | B18: =SUMIFS(Sales_Ledger!$J$5:$J$863,Sales_Ledger!$L$5:$L$863,"Secondary: turnover schedule (Green City Ph1/Ph2 payment history); no monthly turnover register for this period",Sales_Ledger!$D$5:$D$863,2022) | C18: =SUMIFS(Sales_Ledger!$J$5:$J$863,Sales_Ledger!$L$5:$L$863,"Secondary: turnover schedule (Green City Ph1/Ph2 payment history); no monthly turnover register for this period",Sales_Ledger!$D$5:$D$863,2023) | D18: =SUMIFS(Sales_Ledger!$J$5:$J$863,Sales_Ledger!$L$5:$L$863,"Secondary: turnover schedule (Green City Ph1/Ph2 payment history); no monthly turnover register for this period",Sales_Ledger!$D$5:$D$863,2024) | E18: =SUMIFS(Sales_Ledger!$J$5:$J$863,Sales_Ledger!$L$5:$L$863,"Secondary: turnover schedule (Green City Ph1/Ph2 payment history); no monthly turnover register for this period",Sales_Ledger!$D$5:$D$863,2025) | F18: =SUM(B18:E18)
A19: Sales commission records (Jan to Nov 2023, and all of 2025) | B19: =SUMIFS(Sales_Ledger!$J$5:$J$863,Sales_Ledger!$L$5:$L$863,"Secondary: commission records; no monthly turnover register for this period",Sales_Ledger!$D$5:$D$863,2022) | C19: =SUMIFS(Sales_Ledger!$J$5:$J$863,Sales_Ledger!$L$5:$L$863,"Secondary: commission records; no monthly turnover register for this period",Sales_Ledger!$D$5:$D$863,2023) | D19: =SUMIFS(Sales_Ledger!$J$5:$J$863,Sales_Ledger!$L$5:$L$863,"Secondary: commission records; no monthly turnover register for this period",Sales_Ledger!$D$5:$D$863,2024) | E19: =SUMIFS(Sales_Ledger!$J$5:$J$863,Sales_Ledger!$L$5:$L$863,"Secondary: commission records; no monthly turnover register for this period",Sales_Ledger!$D$5:$D$863,2025) | F19: =SUM(B19:E19)
A20: Total | B20: =SUM(B17:B19) | C20: =SUM(C17:C19) | D20: =SUM(D17:D19) | E20: =SUM(E17:E19) | F20: =SUM(F17:F19)
A22: 3. Sales receipts by project / estate and year
A23: Project / estate | B23: 2022 | C23: 2023 | D23: 2024 | E23: 2025 | F23: Total
A24: Baay Foreshore | B24: =SUMIFS(Sales_Ledger!$J$5:$J$863,Sales_Ledger!$G$5:$G$863,$A24,Sales_Ledger!$D$5:$D$863,2022) | C24: =SUMIFS(Sales_Ledger!$J$5:$J$863,Sales_Ledger!$G$5:$G$863,$A24,Sales_Ledger!$D$5:$D$863,2023) | D24: =SUMIFS(Sales_Ledger!$J$5:$J$863,Sales_Ledger!$G$5:$G$863,$A24,Sales_Ledger!$D$5:$D$863,2024) | E24: =SUMIFS(Sales_Ledger!$J$5:$J$863,Sales_Ledger!$G$5:$G$863,$A24,Sales_Ledger!$D$5:$D$863,2025) | F24: =SUM(B24:E24)
A25: Gorge View Court (GVC Gbagada) | B25: =SUMIFS(Sales_Ledger!$J$5:$J$863,Sales_Ledger!$G$5:$G$863,$A25,Sales_Ledger!$D$5:$D$863,2022) | C25: =SUMIFS(Sales_Ledger!$J$5:$J$863,Sales_Ledger!$G$5:$G$863,$A25,Sales_Ledger!$D$5:$D$863,2023) | D25: =SUMIFS(Sales_Ledger!$J$5:$J$863,Sales_Ledger!$G$5:$G$863,$A25,Sales_Ledger!$D$5:$D$863,2024) | E25: =SUMIFS(Sales_Ledger!$J$5:$J$863,Sales_Ledger!$G$5:$G$863,$A25,Sales_Ledger!$D$5:$D$863,2025) | F25: =SUM(B25:E25)
A26: Green City Ibadan (Akinyele-Moniya) | B26: =SUMIFS(Sales_Ledger!$J$5:$J$863,Sales_Ledger!$G$5:$G$863,$A26,Sales_Ledger!$D$5:$D$863,2022) | C26: =SUMIFS(Sales_Ledger!$J$5:$J$863,Sales_Ledger!$G$5:$G$863,$A26,Sales_Ledger!$D$5:$D$863,2023) | D26: =SUMIFS(Sales_Ledger!$J$5:$J$863,Sales_Ledger!$G$5:$G$863,$A26,Sales_Ledger!$D$5:$D$863,2024) | E26: =SUMIFS(Sales_Ledger!$J$5:$J$863,Sales_Ledger!$G$5:$G$863,$A26,Sales_Ledger!$D$5:$D$863,2025) | F26: =SUM(B26:E26)
A27: Green City Phase 1 (Ketu-Epe) | B27: =SUMIFS(Sales_Ledger!$J$5:$J$863,Sales_Ledger!$G$5:$G$863,$A27,Sales_Ledger!$D$5:$D$863,2022) | C27: =SUMIFS(Sales_Ledger!$J$5:$J$863,Sales_Ledger!$G$5:$G$863,$A27,Sales_Ledger!$D$5:$D$863,2023) | D27: =SUMIFS(Sales_Ledger!$J$5:$J$863,Sales_Ledger!$G$5:$G$863,$A27,Sales_Ledger!$D$5:$D$863,2024) | E27: =SUMIFS(Sales_Ledger!$J$5:$J$863,Sales_Ledger!$G$5:$G$863,$A27,Sales_Ledger!$D$5:$D$863,2025) | F27: =SUM(B27:E27)
A28: Green City Phase 1 (Lantaba, Ketu-Epe) | B28: =SUMIFS(Sales_Ledger!$J$5:$J$863,Sales_Ledger!$G$5:$G$863,$A28,Sales_Ledger!$D$5:$D$863,2022) | C28: =SUMIFS(Sales_Ledger!$J$5:$J$863,Sales_Ledger!$G$5:$G$863,$A28,Sales_Ledger!$D$5:$D$863,2023) | D28: =SUMIFS(Sales_Ledger!$J$5:$J$863,Sales_Ledger!$G$5:$G$863,$A28,Sales_Ledger!$D$5:$D$863,2024) | E28: =SUMIFS(Sales_Ledger!$J$5:$J$863,Sales_Ledger!$G$5:$G$863,$A28,Sales_Ledger!$D$5:$D$863,2025) | F28: =SUM(B28:E28)
A29: Green City Phase 2 (Idobi, Ketu-Epe) | B29: =SUMIFS(Sales_Ledger!$J$5:$J$863,Sales_Ledger!$G$5:$G$863,$A29,Sales_Ledger!$D$5:$D$863,2022) | C29: =SUMIFS(Sales_Ledger!$J$5:$J$863,Sales_Ledger!$G$5:$G$863,$A29,Sales_Ledger!$D$5:$D$863,2023) | D29: =SUMIFS(Sales_Ledger!$J$5:$J$863,Sales_Ledger!$G$5:$G$863,$A29,Sales_Ledger!$D$5:$D$863,2024) | E29: =SUMIFS(Sales_Ledger!$J$5:$J$863,Sales_Ledger!$G$5:$G$863,$A29,Sales_Ledger!$D$5:$D$863,2025) | F29: =SUM(B29:E29)
A30: Green City Phase 2 (Ketu-Epe) | B30: =SUMIFS(Sales_Ledger!$J$5:$J$863,Sales_Ledger!$G$5:$G$863,$A30,Sales_Ledger!$D$5:$D$863,2022) | C30: =SUMIFS(Sales_Ledger!$J$5:$J$863,Sales_Ledger!$G$5:$G$863,$A30,Sales_Ledger!$D$5:$D$863,2023) | D30: =SUMIFS(Sales_Ledger!$J$5:$J$863,Sales_Ledger!$G$5:$G$863,$A30,Sales_Ledger!$D$5:$D$863,2024) | E30: =SUMIFS(Sales_Ledger!$J$5:$J$863,Sales_Ledger!$G$5:$G$863,$A30,Sales_Ledger!$D$5:$D$863,2025) | F30: =SUM(B30:E30)
A31: Green City Phase 3 (Omu-Epe) | B31: =SUMIFS(Sales_Ledger!$J$5:$J$863,Sales_Ledger!$G$5:$G$863,$A31,Sales_Ledger!$D$5:$D$863,2022) | C31: =SUMIFS(Sales_Ledger!$J$5:$J$863,Sales_Ledger!$G$5:$G$863,$A31,Sales_Ledger!$D$5:$D$863,2023) | D31: =SUMIFS(Sales_Ledger!$J$5:$J$863,Sales_Ledger!$G$5:$G$863,$A31,Sales_Ledger!$D$5:$D$863,2024) | E31: =SUMIFS(Sales_Ledger!$J$5:$J$863,Sales_Ledger!$G$5:$G$863,$A31,Sales_Ledger!$D$5:$D$863,2025) | F31: =SUM(B31:E31)
A32: Green City Phase 3 Extension (Omu-Epe) | B32: =SUMIFS(Sales_Ledger!$J$5:$J$863,Sales_Ledger!$G$5:$G$863,$A32,Sales_Ledger!$D$5:$D$863,2022) | C32: =SUMIFS(Sales_Ledger!$J$5:$J$863,Sales_Ledger!$G$5:$G$863,$A32,Sales_Ledger!$D$5:$D$863,2023) | D32: =SUMIFS(Sales_Ledger!$J$5:$J$863,Sales_Ledger!$G$5:$G$863,$A32,Sales_Ledger!$D$5:$D$863,2024) | E32: =SUMIFS(Sales_Ledger!$J$5:$J$863,Sales_Ledger!$G$5:$G$863,$A32,Sales_Ledger!$D$5:$D$863,2025) | F32: =SUM(B32:E32)
A33: Heritage Garden | B33: =SUMIFS(Sales_Ledger!$J$5:$J$863,Sales_Ledger!$G$5:$G$863,$A33,Sales_Ledger!$D$5:$D$863,2022) | C33: =SUMIFS(Sales_Ledger!$J$5:$J$863,Sales_Ledger!$G$5:$G$863,$A33,Sales_Ledger!$D$5:$D$863,2023) | D33: =SUMIFS(Sales_Ledger!$J$5:$J$863,Sales_Ledger!$G$5:$G$863,$A33,Sales_Ledger!$D$5:$D$863,2024) | E33: =SUMIFS(Sales_Ledger!$J$5:$J$863,Sales_Ledger!$G$5:$G$863,$A33,Sales_Ledger!$D$5:$D$863,2025) | F33: =SUM(B33:E33)
A34: Housing unit (project not stated in source) | B34: =SUMIFS(Sales_Ledger!$J$5:$J$863,Sales_Ledger!$G$5:$G$863,$A34,Sales_Ledger!$D$5:$D$863,2022) | C34: =SUMIFS(Sales_Ledger!$J$5:$J$863,Sales_Ledger!$G$5:$G$863,$A34,Sales_Ledger!$D$5:$D$863,2023) | D34: =SUMIFS(Sales_Ledger!$J$5:$J$863,Sales_Ledger!$G$5:$G$863,$A34,Sales_Ledger!$D$5:$D$863,2024) | E34: =SUMIFS(Sales_Ledger!$J$5:$J$863,Sales_Ledger!$G$5:$G$863,$A34,Sales_Ledger!$D$5:$D$863,2025) | F34: =SUM(B34:E34)
A35: Land (estate not stated in source) | B35: =SUMIFS(Sales_Ledger!$J$5:$J$863,Sales_Ledger!$G$5:$G$863,$A35,Sales_Ledger!$D$5:$D$863,2022) | C35: =SUMIFS(Sales_Ledger!$J$5:$J$863,Sales_Ledger!$G$5:$G$863,$A35,Sales_Ledger!$D$5:$D$863,2023) | D35: =SUMIFS(Sales_Ledger!$J$5:$J$863,Sales_Ledger!$G$5:$G$863,$A35,Sales_Ledger!$D$5:$D$863,2024) | E35: =SUMIFS(Sales_Ledger!$J$5:$J$863,Sales_Ledger!$G$5:$G$863,$A35,Sales_Ledger!$D$5:$D$863,2025) | F35: =SUM(B35:E35)
... A41: Pacific Court 2 | B41: =SUMIFS(Sales_Ledger!$J$5:$J$863,Sales_Ledger!$G$5:$G$863,$A41,Sales_Ledger!$D$5:$D$863,2022) | C41: =SUMIFS(Sales_Ledger!$J$5:$J$863,Sales_Ledger!$G$5:$G$863,$A41,Sales_Ledger!$D$5:$D$863,2023) | D41: =SUMIFS(Sales_Ledger!$J$5:$J$863,Sales_Ledger!$G$5:$G$863,$A41,Sales_Ledger!$D$5:$D$863,2024) | E41: =SUMIFS(Sales_Ledger!$J$5:$J$863,Sales_Ledger!$G$5:$G$863,$A41,Sales_Ledger!$D$5:$D$863,2025) | F41: =SUM(B41:E41)
A42: Total | B42: =SUM(B24:B41) | C42: =SUM(C24:C41) | D42: =SUM(D24:D41) | E42: =SUM(E24:E41) | F42: =SUM(F24:F41)
A44: 4. Customers subscribed (Subscriptions and Customer_Master)
A45: Subscriptions are counted in the year of the subscription date in the client register.
A46: Subscriptions per client register | B46: 2022 | C46: 2023 | D46: 2024 | E46: 2025 | F46: Total
A47: Land | B47: =COUNTIFS(Subscriptions!$D$5:$D$218,"Land",Subscriptions!$H$5:$H$218,2022) | C47: =COUNTIFS(Subscriptions!$D$5:$D$218,"Land",Subscriptions!$H$5:$H$218,2023) | D47: =COUNTIFS(Subscriptions!$D$5:$D$218,"Land",Subscriptions!$H$5:$H$218,2024) | E47: =COUNTIFS(Subscriptions!$D$5:$D$218,"Land",Subscriptions!$H$5:$H$218,2025) | F47: =SUM(B47:E47)
A48: Housing | B48: =COUNTIFS(Subscriptions!$D$5:$D$218,"Housing",Subscriptions!$H$5:$H$218,2022) | C48: =COUNTIFS(Subscriptions!$D$5:$D$218,"Housing",Subscriptions!$H$5:$H$218,2023) | D48: =COUNTIFS(Subscriptions!$D$5:$D$218,"Housing",Subscriptions!$H$5:$H$218,2024) | E48: =COUNTIFS(Subscriptions!$D$5:$D$218,"Housing",Subscriptions!$H$5:$H$218,2025) | F48: =SUM(B48:E48)
A49: Construction | B49: =COUNTIFS(Subscriptions!$D$5:$D$218,"Construction",Subscriptions!$H$5:$H$218,2022) | C49: =COUNTIFS(Subscriptions!$D$5:$D$218,"Construction",Subscriptions!$H$5:$H$218,2023) | D49: =COUNTIFS(Subscriptions!$D$5:$D$218,"Construction",Subscriptions!$H$5:$H$218,2024) | E49: =COUNTIFS(Subscriptions!$D$5:$D$218,"Construction",Subscriptions!$H$5:$H$218,2025) | F49: =SUM(B49:E49)
...

Sheet Notes
A1: Basis of preparation, sources and limitations
A4: Purpose
A5: Scope | B5: All sales records across land, housing and construction for 1 Jan 2023 to 31 Dec 2025, with 2022 included where records exist, plus every customer who subscribed in that window. Prepared for the external auditor from files on the BAAY Google Drive. Xero was not used.
A6: What the figures are | B6: Cash receipts from customers as recorded by Accounts and Client Relations. They are not revenue: under IFRS 15, housing revenue is recognised at handover and instalment land sales on transfer of control, so receipts will not equal the revenue line in the audited accounts.
A8: Source files (Google Drive)
A9: BAAY PROJECTS FINANCIALS 2024.xlsx | B9: Owner baayrealty@gmail.com. Monthly turnover sheets DECEMBER 2023 TURNOVER to DECEMBER TURNOVER (2024), split by Allen and Magodo branches from July 2024; TURNOVER SCHEDULE (Green City Phase 1 and 2 payment histories, 2023 to 2024). https://drive.google.com/file/d/1xxPmuhTO7yU2Xj4dTlhJLBm4G8uQ0djH/view
A10: BAAY PROJECTS SALES EXPENSES (COMMISSION) RECORDS (1) | B10: Owner finance.baayprojects@gmail.com, live Google Sheet (latest version, edited 2 Oct 2026). One tab per realtor/associate listing each client payment on which commission was computed. Tabs RESERVE, ASSOCIATE LEAD and 2% UPLINE were not used because they restate the same sales. https://docs.google.com/spreadsheets/d/1d6rtbsgtIV7EDgoHHqDDx_pL2jXcNY92DPUl5KqOXg8
A11: BAAY PROJECTS CLIENTS | B11: Owner baayrealty@gmail.com. Client register maintained by Client Relations: one tab per estate/project with subscription date, price, amount paid, payment plan, allocation and contacts. https://docs.google.com/spreadsheets/d/1DRFmvVuOpeHsLXLAUwPu5Y37A_mOiNGEEYaO8-mRS2o
A12: BAAY FORESHORE, IBADAN EXPENSES, SUBSCRIBERS & FINANCIALS | B12: Owner acct.baayprojects@gmail.com. Tab REVENUE/FINACIALS BY SUBSCRIBERS used for Baay Foreshore subscribers in 2025 (cost, payment, plan). https://docs.google.com/spreadsheets/d/10QOMlmpicusYlxha1Q1CMPboSlq193dtaN_DveSicyg
A13: Searched, not used | B13: BAAY PROJECTS Revenue and Expense Register 2026 and BAAY PROJECTS FINANCIALS 2026 (2026 only); BAAY_Management_Accounts_Workshop.xlsx (2026 journals); audited financial statement PDFs (no customer-level detail); payroll files.
A15: How each year was built
A16: 2022 | B16: No transaction-level receipts exist on the Drive for 2022. Customers subscribed in 2022 (Pacific Court) are listed from the client register only.
A17: Jan to Nov 2023 | B17: No monthly turnover register exists for this period. Receipts come from the TURNOVER SCHEDULE (Green City Phase 1 and 2 only) and from the commission records; a commission line that matches a schedule line is not counted twice.
A18: Dec 2023 to Dec 2024 | B18: The monthly turnover register is the population. Turnover-schedule and commission lines that match a register line one-to-one are shown in the "Also recorded in" column. Lines that do not match are listed on Exceptions_Dec23_Dec24 and are NOT added, because most are aggregates or splits of register receipts; adding them would double count.
A19: 2025 | B19: No turnover register for 2025 exists on the Drive. Receipts come from the commission records, de-duplicated across realtor tabs. Commission records only capture sales that carried commission, and a single line can aggregate several transfers, so 2025 should be treated as a list for testing against bank statements, not a complete cash book.
A20: Construction | B20: No construction-contract receipts were found for 2022 to 2025 in any source. The first construction engagement in the records (12 Basket apartment renovation) is dated February 2026, outside this period.
A22: Processing rules
A23: Dates | B23: Several source sheets store dates typed as day/month but read by the spreadsheet as month/day (e.g. 1 December 2023 held as 12 January 2023). Day and month were swapped back for those cells; the sequence of each client's instalments and the month of each turnover sheet confirm the correction. The date exactly as stored is kept in the "Date as recorded" column. Obvious year typos (e.g. 3034, 0204) are noted and the line is reported in the month of the sheet it sits on.
A24: Duplicates | B24: Commission tabs restate earlier payments in each payout block, and the same sale can sit on two realtor tabs. Exact repeats within a tab were dropped; across tabs, lines for the same customer and amount within 45 days were treated as one receipt (cross-reference kept).
A25: Customer matching | B25: Names were matched across sources after removing titles (Mr, Mrs, Dr, Engr, etc.) and comparing the remaining name parts. Each person has one Customer ID. Matching is approximate: a misspelt name can create a second ID, so review the Customer_Master flags.
A26: Exclusions | B26: Co-ownership receipts (a fixed-return investment product, not a sale), credit memos (non-cash transfers between products) and service/engagement income are removed to the Exclusions tab, so the turnover sheet totals still reconcile on Turnover_Recon.
A27: Contact details | B27: Phone and email are included only for customer confirmation work. Dates of birth held in the client register were left out.
A29: Points the auditor should know
A30: 1 | B30: Agree receipts to bank statements, especially 2025 and the Exceptions tab.
A31: 2 | B31: 9 register entries dated in 2026 were left out of Subscriptions (outside the period).
A32: 3 | B32: Customer_Master column R flags customers whose receipts exceed the contract value in the register (possible duplicate entries, a second plot, or ancillary fees) and customers who appear in transaction records but not in the client register.
A33: 4 | B33: Contract values and paid-to-date figures on Subscriptions are as typed by Client Relations and were not recomputed.

Sheet Sales_Ledger
A1: BAAY Projects Limited: Sales receipts ledger, land and housing (Jan 2023 to Dec 2025)
A2: One row per customer receipt. Source, row and recorded date kept for every line so each can be traced back. Amounts in Naira.
A4: Ref | B4: Receipt date | C4: Reporting month | D4: Year | E4: Product line | F4: Receipt type | G4: Project / estate | H4: Customer ID | I4: Customer name (as recorded) | J4: Amount (₦) | K4: Branch | L4: Population basis | M4: Source file | N4: Source sheet | O4: Source row | P4: Date as recorded in source | Q4: Also recorded in | R4: Review note
A5: SL0001 | B5: 44957 | C5: 2023-01 | D5: 2023 | E5: Land | F5: Plot / unit price | G5: Land (estate not stated in source) | H5: BP-C0006 | I5: Mr Olasupo Oladimeji | J5: 894000 | L5: Secondary: commission records; no monthly turnover register for this period | M5: BAAY PROJECTS SALES EXPENSES (COMMISSION) RECORDS (1) | N5: MRS ABIMBOLA | O5: 15 | P5: 31/01/2023 | R5: Commission-record amount: confirm to bank statement (records can aggregate several transfers)
A6: SL0002 | B6: 44987 | C6: 2023-03 | D6: 2023 | E6: Land | F6: Plot / unit price | G6: Green City Phase 2 (Ketu-Epe) | H6: BP-C0009 | I6: Miss Oji Blessing Mary | J6: 740000 | L6: Secondary: turnover schedule (Green City Ph1/Ph2 payment history); no monthly turnover register for this period | M6: BAAY PROJECTS FINANCIALS 2024.xlsx | N6: TURNOVER SCHEDULE | O6: 111 | P6: 2023-02-03
A7: SL0003 | B7: 45059 | C7: 2023-05 | D7: 2023 | E7: Land | F7: Plot / unit price | G7: Land (estate not stated in source) | H7: BP-C0010 | I7: Mrs Yohanna Paulina | J7: 300000 | L7: Secondary: commission records; no monthly turnover register for this period | M7: BAAY PROJECTS SALES EXPENSES (COMMISSION) RECORDS (1) | N7: MR CHARLES | O7: 44 | P7: 13/05/2023 | R7: Commission-record amount: confirm to bank statement (records can aggregate several transfers)
A8: SL0004 | B8: 45063 | C8: 2023-05 | D8: 2023 | E8: Land | F8: Plot / unit price | G8: Green City Phase 2 (Ketu-Epe) | H8: BP-C0012 | I8: Mr Apiafi Imiebam | J8: 1000000 | L8: Secondary: turnover schedule (Green City Ph1/Ph2 payment history); no monthly turnover register for this period | M8: BAAY PROJECTS FINANCIALS 2024.xlsx | N8: TURNOVER SCHEDULE | O8: 310 | P8: 17/05/2023
A9: SL0005 | B9: 45076 | C9: 2023-05 | D9: 2023 | E9: Land | F9: Plot / unit price | G9: Green City Phase 1 (Ketu-Epe) | H9: BP-C0013 | I9: Mr Tijani Moshood Abiola | J9: 1000000 | L9: Secondary: turnover schedule (Green City Ph1/Ph2 payment history); no monthly turnover register for this period | M9: BAAY PROJECTS FINANCIALS 2024.xlsx | N9: TURNOVER SCHEDULE | O9: 282 | P9: 30/05/2023
A10: SL0006 | B10: 45092 | C10: 2023-06 | D10: 2023 | E10: Land | F10: Plot / unit price | G10: Land (estate not stated in source) | H10: BP-C0015 | I10: Mr Damilare Ositade Owolabi | J10: 1500000 | L10: Secondary: commission records; no monthly turnover register for this period | M10: BAAY PROJECTS SALES EXPENSES (COMMISSION) RECORDS (1) | N10: IDARA EKANEMI | O10: 7 | P10: 15/06/2023 | R10: Commission-record amount: confirm to bank statement (records can aggregate several transfers)
A11: SL0007 | B11: 45152 | C11: 2023-08 | D11: 2023 | E11: Land | F11: Plot / unit price | G11: Land (estate not stated in source) | H11: BP-C0019 | I11: Mr Ogbu Pius Ejaka | J11: 1500000 | L11: Secondary: commission records; no monthly turnover register for this period | M11: BAAY PROJECTS SALES EXPENSES (COMMISSION) RECORDS (1) | N11: MS BLESSING | O11: 90 | P11: 14/08/2023 | Q11: MS MAYOWA BRAIMOH r19 | R11: Commission-record amount: confirm to bank statement (records can aggregate several transfers)
A12: SL0008 | B12: 45161 | C12: 2023-08 | D12: 2023 | E12: Land | F12: Plot / unit price | G12: Land (estate not stated in source) | H12: BP-C0021 | I12: Mr Oyewusi sheriff Oyewole | J12: 1000000 | L12: Secondary: commission records; no monthly turnover register for this period | M12: BAAY PROJECTS SALES EXPENSES (COMMISSION) RECORDS (1) | N12: MS BOLANLE | O12: 7 | P12: 23/08/2023 | R12: Commission-record amount: confirm to bank statement (records can aggregate several transfers)
A13: SL0009 | B13: 45173 | C13: 2023-09 | D13: 2023 | E13: Land | F13: Plot / unit price | G13: Land (estate not stated in source) | H13: BP-C0025 | I13: Mrs Obadara Dorcas Adebisi | J13: 1500000 | L13: Secondary: commission records; no monthly turnover register for this period | M13: BAAY PROJECTS SALES EXPENSES (COMMISSION) RECORDS (1) | N13: NELSON | O13: 7 | P13: 2023-04-09 | R13: Commission-record amount: confirm to bank statement (records can aggregate several transfers)
A14: SL0010 | B14: 45184 | C14: 2023-09 | D14: 2023 | E14: Land | F14: Plot / unit price | G14: Green City Phase 1 (Ketu-Epe) | H14: BP-C0026 | I14: Mr Adebayo Dada | J14: 400000 | L14: Secondary: turnover schedule (Green City Ph1/Ph2 payment history); no monthly turnover register for this period | M14: BAAY PROJECTS FINANCIALS 2024.xlsx | N14: TURNOVER SCHEDULE | O14: 6 | P14: 15/09/2023
A15: SL0011 | B15: 45190 | C15: 2023-09 | D15: 2023 | E15: Land | F15: Plot / unit price | G15: Green City Phase 1 (Ketu-Epe) | H15: BP-C0027 | I15: Mr Edun Ayobami Simeon | J15: 1000000 | L15: Secondary: turnover schedule (Green City Ph1/Ph2 payment history); no monthly turnover register for this period | M15: BAAY PROJECTS FINANCIALS 2024.xlsx | N15: TURNOVER SCHEDULE | O15: 125 | P15: 21/09/2023 | Q15: OLAIYA r7
A16: SL0012 | B16: 45190 | C16: 2023-09 | D16: 2023 | E16: Land | F16: Plot / unit price | G16: Land (estate not stated in source) | H16: BP-C0018 | I16: Mr Sunday Gideon | J16: 1500000 | L16: Secondary: commission records; no monthly turnover register for this period | M16: BAAY PROJECTS SALES EXPENSES (COMMISSION) RECORDS (1) | N16: MS BLESSING | O16: 7 | P16: 21/09/2023 | R16: Commission-record amount: confirm to bank statement (records can aggregate several transfers)
A17: SL0013 | B17: 45197 | C17: 2023-09 | D17: 2023 | E17: Land | F17: Plot / unit price | G17: Green City Phase 1 (Ketu-Epe) | H17: BP-C0028 | I17: Mr Adebanjo Isaac | J17: 1000000 | L17: Secondary: turnover schedule (Green City Ph1/Ph2 payment history); no monthly turnover register for this period | M17: BAAY PROJECTS FINANCIALS 2024.xlsx | N17: TURNOVER SCHEDULE | O17: 198 | P17: 28/09/2023
A18: SL0014 | B18: 45197 | C18: 2023-09 | D18: 2023 | E18: Land | F18: Plot / unit price | G18: Green City Phase 1 (Ketu-Epe) | H18: BP-C0026 | I18: Mr Adebayo Dada | J18: 300000 | L18: Secondary: turnover schedule (Green City Ph1/Ph2 payment history); no monthly turnover register for this period | M18: BAAY PROJECTS FINANCIALS 2024.xlsx | N18: TURNOVER SCHEDULE | O18: 7 | P18: 28/09/2023
A19: SL0015 | B19: 45197 | C19: 2023-09 | D19: 2023 | E19: Land | F19: Plot / unit price | G19: Land (estate not stated in source) | H19: BP-C0021 | I19: Mr Oyewusi sheriff Oyewole | J19: 1000000 | L19: Secondary: commission records; no monthly turnover register for this period | M19: BAAY PROJECTS SALES EXPENSES (COMMISSION) RECORDS (1) | N19: MS BOLANLE | O19: 8 | P19: 28/09/2023 | R19: Commission-record amount: confirm to bank statement (records can aggregate several transfers)
A20: SL0016 | B20: 45202 | C20: 2023-10 | D20: 2023 | E20: Land | F20: Plot / unit price | G20: Green City Phase 1 (Ketu-Epe) | H20: BP-C0030 | I20: Mr Akorede Adese | J20: 1000000 | L20: Secondary: turnover schedule (Green City Ph1/Ph2 payment history); no monthly turnover register for this period | M20: BAAY PROJECTS FINANCIALS 2024.xlsx | N20: TURNOVER SCHEDULE | O20: 202 | P20: 2023-03-10
A21: SL0017 | B21: 45202 | C21: 2023-10 | D21: 2023 | E21: Land | F21: Plot / unit price | G21: Green City Phase 1 (Ketu-Epe) | H21: BP-C0030 | I21: Mr Akorede Adese | J21: 100000 | L21: Secondary: turnover schedule (Green City Ph1/Ph2 payment history); no monthly turnover register for this period | M21: BAAY PROJECTS FINANCIALS 2024.xlsx | N21: TURNOVER SCHEDULE | O21: 203 | P21: 2023-03-10
A22: SL0018 | B22: 45202 | C22: 2023-10 | D22: 2023 | E22: Land | F22: Plot / unit price | G22: Land (estate not stated in source) | H22: BP-C0029 | I22: Mr Ohanehi Anthony | J22: 3000000 | L22: Secondary: commission records; no monthly turnover register for this period | M22: BAAY PROJECTS SALES EXPENSES (COMMISSION) RECORDS (1) | N22: MS IMMACULATE | O22: 8 | P22: 2023-03-10 | R22: Commission-record amount: confirm to bank statement (records can aggregate several transfers)
A23: SL0019 | B23: 45202 | C23: 2023-10 | D23: 2023 | E23: Land | F23: Plot / unit price | G23: Green City Phase 1 (Ketu-Epe) | H23: BP-C0008 | I23: Mr Roqeeb Rasaq Adebare | J23: 300000 | L23: Secondary: turnover schedule (Green City Ph1/Ph2 payment history); no monthly turnover register for this period | M23: BAAY PROJECTS FINANCIALS 2024.xlsx | N23: TURNOVER SCHEDULE | O23: 182 | P23: 2023-03-10
A24: SL0020 | B24: 45202 | C24: 2023-10 | D24: 2023 | E24: Land | F24: Plot / unit price | G24: Green City Phase 1 (Ketu-Epe) | H24: BP-C0008 | I24: Mr Roqeeb Rasaq Adebare | J24: 200000 | L24: Secondary: turnover schedule (Green City Ph1/Ph2 payment history); no monthly turnover register for this period | M24: BAAY PROJECTS FINANCIALS 2024.xlsx | N24: TURNOVER SCHEDULE | O24: 183 | P24: 2023-03-10
A25: SL0021 | B25: 45205 | C25: 2023-10 | D25: 2023 | E25: Land | F25: Plot / unit price | G25: Land (estate not stated in source) | H25: BP-C0026 | I25: Mr & Mrs Adebayo Dada | J25: 3000000 | L25: Secondary: commission records; no monthly turnover register for this period | M25: BAAY PROJECTS SALES EXPENSES (COMMISSION) RECORDS (1) | N25: MRS ABIMBOLA | O25: 7 | P25: 2023-06-10 | R25: Commission-record amount: confirm to bank statement (records can aggregate several transfers)
A26: SL0022 | B26: 45205 | C26: 2023-10 | D26: 2023 | E26: Land | F26: Plot / unit price | G26: Green City Phase 1 (Ketu-Epe) | H26: BP-C0026 | I26: Mr Adebayo Dada | J26: 300000 | L26: Secondary: turnover schedule (Green City Ph1/Ph2 payment history); no monthly turnover register for this period | M26: BAAY PROJECTS FINANCIALS 2024.xlsx | N26: TURNOVER SCHEDULE | O26: 8 | P26: 2023-06-10
A27: SL0023 | B27: 45209 | C27: 2023-10 | D27: 2023 | E27: Land | F27: Plot / unit price | G27: Land (estate not stated in source) | H27: BP-C0029 | I27: Mr Ohanehi Anthony | J27: 1500000 | L27: Secondary: commission records; no monthly turnover register for this period | M27: BAAY PROJECTS SALES EXPENSES (COMMISSION) RECORDS (1) | N27: MS IMMACULATE | O27: 7 | P27: 2023-10-10 | R27: Commission-record amount: confirm to bank statement (records can aggregate several transfers)
A28: SL0024 | B28: 45211 | C28: 2023-10 | D28: 2023 | E28: Land | F28: Plot / unit price | G28: Green City Phase 1 (Ketu-Epe) | H28: BP-C0033 | I28: Mr Olumoko Oladapo Oluwaseun | J28: 1000000 | L28: Secondary: turnover schedule (Green City Ph1/Ph2 payment history); no monthly turnover register for this period | M28: BAAY PROJECTS FINANCIALS 2024.xlsx | N28: TURNOVER SCHEDULE | O28: 155 | P28: 2023-12-10 | Q28: MS BOLANLE r12
A29: SL0025 | B29: 45211 | C29: 2023-10 | D29: 2023 | E29: Land | F29: Plot / unit price | G29: Land (estate not stated in source) | H29: BP-C0034 | I29: Mrs Ndubuisi Ujunwa | J29: 1500000 | L29: Secondary: commission records; no monthly turnover register for this period | M29: BAAY PROJECTS SALES EXPENSES (COMMISSION) RECORDS (1) | N29: MS IMMACULATE | O29: 9 | P29: 2023-12-10 | R29: Commission-record amount: confirm to bank statement (records can aggregate several transfers)
A30: SL0026 | B30: 45219 | C30: 2023-10 | D30: 2023 | E30: Land | F30: Plot / unit price | G30: Land (estate not stated in source) | H30: BP-C0021 | I30: Mr Oyewusi sheriff Oyewole | J30: 1000000 | L30: Secondary: commission records; no monthly turnover register for this period | M30: BAAY PROJECTS SALES EXPENSES (COMMISSION) RECORDS (1) | N30: MS BOLANLE | O30: 9 | P30: 20/10/2023 | R30: Commission-record amount: confirm to bank statement (records can aggregate several transfers)
A31: SL0027 | B31: 45222 | C31: 2023-10 | D31: 2023 | E31: Land | F31: Plot / unit price | G31: Green City Phase 1 (Ketu-Epe) | H31: BP-C0027 | I31: Mr Edun Ayobami Simeon | J31: 700000 | L31: Secondary: turnover schedule (Green City Ph1/Ph2 payment history); no monthly turnover register for this period | M31: BAAY PROJECTS FINANCIALS 2024.xlsx | N31: TURNOVER SCHEDULE | O31: 126 | P31: 23/10/2023 | Q31: OLAIYA r8
A32: SL0028 | B32: 45226 | C32: 2023-10 | D32: 2023 | E32: Land | F32: Plot / unit price | G32: Green City Phase 1 (Ketu-Epe) | H32: BP-C0033 | I32: Mr Olumoko Oladapo Oluwaseun | J32: 1000000 | L32: Secondary: turnover schedule (Green City Ph1/Ph2 payment history); no monthly turnover register for this period | M32: BAAY PROJECTS FINANCIALS 2024.xlsx | N32: TURNOVER SCHEDULE | O32: 156 | P32: 27/10/2023 | Q32: MS BOLANLE r13
A33: SL0029 | B33: 45227 | C33: 2023-10 | D33: 2023 | E33: Land | F33: Plot / unit price | G33: Green City Phase 1 (Ketu-Epe) | H33: BP-C0036 | I33: Mr Ohumende Paul Osaze | J33: 3000000 | L33: Secondary: turnover schedule (Green City Ph1/Ph2 payment history); no monthly turnover register for this period | M33: BAAY PROJECTS FINANCIALS 2024.xlsx | N33: TURNOVER SCHEDULE | O33: 117 | P33: 28/10/2023
A34: SL0030 | B34: 45228 | C34: 2023-10 | D34: 2023 | E34: Land | F34: Plot / unit price | G34: Land (estate not stated in source) | H34: BP-C0029 | I34: Mr Ohanehi Anthony | J34: 9000000 | L34: Secondary: commission records; no monthly turnover register for this period | M34: BAAY PROJECTS SALES EXPENSES (COMMISSION) RECORDS (1) | N34: MS IMMACULATE | O34: 10 | P34: 29/10/2023 | R34: Commission-record amount: confirm to bank statement (records can aggregate several transfers)
A35: SL0031 | B35: 45228 | C35: 2023-10 | D35: 2023 | E35: Land | F35: Plot / unit price | G35: Land (estate not stated in source) | H35: BP-C0038 | I35: Okeizie Ifeoma Mandy | J35: 2000000 | L35: Secondary: commission records; no monthly turnover register for this period | M35: BAAY PROJECTS SALES EXPENSES (COMMISSION) RECORDS (1) | N35: MS CELINA | O35: 7 | P35: 29/10/2023 | R35: Commission-record amount: confirm to bank statement (records can aggregate several transfers)
A36: SL0032 | B36: 45229 | C36: 2023-10 | D36: 2023 | E36: Land | F36: Plot / unit price | G36: Land (estate not stated in source) | H36: BP-C0040 | I36: Bassey Christopher | J36: 9000000 | L36: Secondary: commission records; no monthly turnover register for this period | M36: BAAY PROJECTS SALES EXPENSES (COMMISSION) RECORDS (1) | N36: MS IMMACULATE | O36: 11 | P36: 30/10/2023 | R36: Commission-record amount: confirm to bank statement (records can aggregate several transfers)
A37: SL0033 | B37: 45229 | C37: 2023-10 | D37: 2023 | E37: Land | F37: Plot / unit price | G37: Land (estate not stated in source) | H37: BP-C0040 | I37: Bassey Christopher | J37: 3000000 | L37: Secondary: commission records; no monthly turnover register for this period | M37: BAAY PROJECTS SALES EXPENSES (COMMISSION) RECORDS (1) | N37: MS IMMACULATE | O37: 12 | P37: 30/10/2023 | R37: Commission-record amount: confirm to bank statement (records can aggregate several transfers)
A38: SL0034 | B38: 45229 | C38: 2023-10 | D38: 2023 | E38: Land | F38: Plot / unit price | G38: Green City Phase 1 (Ketu-Epe) | H38: BP-C0030 | I38: Mr Akorede Adese | J38: 100000 | L38: Secondary: turnover schedule (Green City Ph1/Ph2 payment history); no monthly turnover register for this period | M38: BAAY PROJECTS FINANCIALS 2024.xlsx | N38: TURNOVER SCHEDULE | O38: 204 | P38: 30/10/2023
A39: SL0035 | B39: 45229 | C39: 2023-10 | D39: 2023 | E39: Land | F39: Plot / unit price | G39: Green City Phase 2 (Ketu-Epe) | H39: BP-C0039 | I39: Mr Alabi Abdulazeez | J39: 1000000 | L39: Secondary: turnover schedule (Green City Ph1/Ph2 payment history); no monthly turnover register for this period | M39: BAAY PROJECTS FINANCIALS 2024.xlsx | N39: TURNOVER SCHEDULE | O39: 195 | P39: 30/10/2023
A40: SL0036 | B40: 45229 | C40: 2023-10 | D40: 2023 | E40: Land | F40: Plot / unit price | G40: Green City Phase 1 (Ketu-Epe) | H40: BP-C0029 | I40: Mr Ohanehi Anthony Chukwunonso | J40: 1000000 | L40: Secondary: turnover schedule (Green City Ph1/Ph2 payment history); no monthly turnover register for this period | M40: BAAY PROJECTS FINANCIALS 2024.xlsx | N40: TURNOVER SCHEDULE | O40: 17 | P40: 30/10/2023
A41: SL0037 | B41: 45229 | C41: 2023-10 | D41: 2023 | E41: Land | F41: Plot / unit price | G41: Green City Phase 1 (Ketu-Epe) | H41: BP-C0029 | I41: Mr Ohanehi Anthony Chukwunonso | J41: 1000000 | L41: Secondary: turnover schedule (Green City Ph1/Ph2 payment history); no monthly turnover register for this period | M41: BAAY PROJECTS FINANCIALS 2024.xlsx | N41: TURNOVER SCHEDULE | O41: 163 | P41: 30/10/2023
...

Sheet Subscriptions
A1: Customer subscriptions per client register (subscribed Jan 2022 to Dec 2025)
A2: One row per customer per project, as recorded by Client Relations. Contract value and paid-to-date are as stated in the register, not recomputed.
A4: Sub ref | B4: Customer ID | C4: Customer name (register) | D4: Product line | E4: Project / estate | F4: Unit / plot | G4: Subscription date | H4: Year | I4: Contract value (₦) | J4: Paid to date per register (₦) | K4: Balance per register (₦) | L4: Payment plan | M4: Status | N4: Allocation | O4: Documents stage | P4: Realtor / contact | Q4: Source sheet | R4: Source row | S4: Date as recorded | T4: Note
A5: SB0001 | B5: BP-C0001 | C5: Mr Meshack Osagie | D5: Housing | E5: Pacific Court | F5: terrace | units: 3.0 | G5: 44593 | H5: =IF(G5="","",YEAR(G5)) | I5: 10500000 | K5: =IF(OR(I5="",J5=""),"",I5-J5) | L5: 15MONTHS | M5: PAID | P5: AKIN PHILIP | Q5: BAAY PROJECTS CLIENTS > PACIFIC COURT INVESTORS LIST | R5: 2 | S5: 2022-02-01
A6: SB0002 | B6: BP-C0002 | C6: Temidayo Oniosun | D6: Housing | E6: Pacific Court | F6: fully detached | units: 1.0 | G6: 44652 | H6: =IF(G6="","",YEAR(G6)) | I6: 52200000 | K6: =IF(OR(I6="",J6=""),"",I6-J6) | L6: 5MONTHS | M6: PAID | P6: MD | Q6: BAAY PROJECTS CLIENTS > PACIFIC COURT INVESTORS LIST | R6: 3 | S6: 2022-04-01
A7: SB0003 | B7: BP-C0003 | C7: Mrs Agbaje | D7: Housing | E7: Pacific Court | F7: fully detached | units: 1.0 | G7: 44713 | H7: =IF(G7="","",YEAR(G7)) | I7: 63000000 | K7: =IF(OR(I7="",J7=""),"",I7-J7) | L7: 10MONTHS | M7: PAID | P7: MR BIOLA AKOSILE | Q7: BAAY PROJECTS CLIENTS > PACIFIC COURT INVESTORS LIST | R7: 4 | S7: 2022-06-01
A8: SB0004 | B8: BP-C0004 | C8: Mrs Kate | D8: Housing | E8: Pacific Court | F8: terrace | units: 1.0 | G8: 44774 | H8: =IF(G8="","",YEAR(G8)) | I8: 40000000 | K8: =IF(OR(I8="",J8=""),"",I8-J8) | L8: 24MONTHS | M8: REFUND | P8: MD | Q8: BAAY PROJECTS CLIENTS > PACIFIC COURT INVESTORS LIST | R8: 5 | S8: 2022-08-01
A9: SB0005 | B9: BP-C0005 | C9: Mrs Mo | D9: Housing | E9: Pacific Court | F9: terrace | units: 1.0 | G9: 44896 | H9: =IF(G9="","",YEAR(G9)) | I9: 47000000 | K9: =IF(OR(I9="",J9=""),"",I9-J9) | L9: 10MONTHS | M9: PAID | P9: MS YETUNDE ABISOYE | Q9: BAAY PROJECTS CLIENTS > PACIFIC COURT INVESTORS LIST | R9: 6 | S9: 2022-12-01
A10: SB0006 | B10: BP-C0007 | C10: Mrs Ero | D10: Housing | E10: Pacific Court | F10: fully detached | units: 1.0 | G10: 44958 | H10: =IF(G10="","",YEAR(G10)) | I10: 600000000 | K10: =IF(OR(I10="",J10=""),"",I10-J10) | L10: 3MONTHS | M10: PAID | P10: PASTOR GABRIEL | Q10: BAAY PROJECTS CLIENTS > PACIFIC COURT INVESTORS LIST | R10: 7 | S10: 2023-02-01
A11: SB0007 | B11: BP-C0008 | C11: Mr Rasaq Roqeeb | D11: Land | E11: Green City Phase 1 (Lantaba, Ketu-Epe) | F11: 250sqm | G11: 44967 | H11: =IF(G11="","",YEAR(G11)) | I11: 3900000 | J11: 3900000 | K11: =IF(OR(I11="",J11=""),"",I11-J11) | L11: 6 months | M11: Bought | N11: BLOCK F1 | O11: Collected by Client | P11: MD | Q11: BAAY PROJECTS CLIENTS > GREEN CITY KETU 1 INVESTORS LIS | R11: 29 | S11: 2023-10-02
A12: SB0008 | B12: BP-C0011 | C12: OLAIYA SUNDAY TEMITOPE | D12: Land | E12: Green City Phase 1 (Lantaba, Ketu-Epe) | F12: 600sqm | G12: 45061 | H12: =IF(G12="","",YEAR(G12)) | I12: 1500000 | J12: 1500000 | K12: =IF(OR(I12="",J12=""),"",I12-J12) | L12: 3months | M12: Bought | N12: BLOCK E2 | O12: Yet to collect Physical Document with MD | P12: Ms Abimbola | Q12: BAAY PROJECTS CLIENTS > GREEN CITY KETU 1 INVESTORS LIS | R12: 4 | S12: 15/05/2023
A13: SB0009 | B13: BP-C0013 | C13: MOSHOOD TIJANI | D13: Land | E13: Green City Phase 1 (Lantaba, Ketu-Epe) | F13: 250sqm | G13: 45073 | H13: =IF(G13="","",YEAR(G13)) | I13: 1500000 | J13: 1400000 | K13: =IF(OR(I13="",J13=""),"",I13-J13) | L13: 3months | M13: Bought | N13: BLOCK B2A | O13: Yet to collect Deeed | P13: MD | Q13: BAAY PROJECTS CLIENTS > GREEN CITY KETU 1 INVESTORS LIS | R13: 3 | S13: 27/05/2023
A14: SB0010 | B14: BP-C0014 | C14: PROF OLUGBENGA AKINADE/MRS ARAWOMO OMOLOLA | D14: Land | E14: Green City Phase 1 (Lantaba, Ketu-Epe) | F14: 500sqm | G14: 45083 | H14: =IF(G14="","",YEAR(G14)) | I14: 3600000 | J14: 3600000 | K14: =IF(OR(I14="",J14=""),"",I14-J14) | L14: 3months | M14: Bought | N14: BLOCK D7 | O14: Physical Document Collected | P14: MD | Q14: BAAY PROJECTS CLIENTS > GREEN CITY KETU 1 INVESTORS LIS | R14: 5 | S14: 2023-06-06
A15: SB0011 | B15: BP-C0015 | C15: MR Damilare Ositade Owolabi | D15: Land | E15: Green City Phase 1 (Lantaba, Ketu-Epe) | F15: 250sqm | G15: 45092 | H15: =IF(G15="","",YEAR(G15)) | I15: 1500000 | J15: 1500000 | K15: =IF(OR(I15="",J15=""),"",I15-J15) | L15: 3months | M15: Bought | N15: BLOCK D4B | O15: Yet to collect Physical Document | P15: IDARA | Q15: BAAY PROJECTS CLIENTS > GREEN CITY KETU 1 INVESTORS LIS | R15: 7 | S15: 15/06/2023
A16: SB0012 | B16: BP-C0016 | C16: Mr Tobi Adesina | D16: Land | E16: Green City Phase 1 (Lantaba, Ketu-Epe) | F16: 250sqm | G16: 45103 | H16: =IF(G16="","",YEAR(G16)) | I16: 1500000 | K16: =IF(OR(I16="",J16=""),"",I16-J16) | M16: incentives | N16: BLOCK D6A | O16: Collected by Client | P16: TOBY AND TYE | Q16: BAAY PROJECTS CLIENTS > GREEN CITY KETU 1 INVESTORS LIS | R16: 8 | S16: 26/06/2023 | T16: Paid-to-date in source: PARTNERSHIP
A17: SB0013 | B17: BP-C0017 | C17: Mr. Taiwo John Adeleye. | D17: Land | E17: Green City Phase 1 (Lantaba, Ketu-Epe) | F17: 250sqm | G17: 45129 | H17: =IF(G17="","",YEAR(G17)) | I17: 1500000 | J17: 1500000 | K17: =IF(OR(I17="",J17=""),"",I17-J17) | L17: 3months | M17: bought | N17: BLOCK D5b | O17: Collected by Client | P17: MD | Q17: BAAY PROJECTS CLIENTS > GREEN CITY KETU 1 INVESTORS LIS | R17: 10 | S17: 22/07/2023
A18: SB0014 | B18: BP-C0018 | C18: Mr Sunday Gideon | D18: Land | E18: Green City Phase 1 (Lantaba, Ketu-Epe) | F18: 250sqm | G18: 45137 | H18: =IF(G18="","",YEAR(G18)) | I18: 1500000 | J18: 1500000 | K18: =IF(OR(I18="",J18=""),"",I18-J18) | L18: Outright | M18: bought | N18: BLOCK D5A | O18: Collected by client | P18: MS BLESSING | Q18: BAAY PROJECTS CLIENTS > GREEN CITY KETU 1 INVESTORS LIS | R18: 9 | S18: 30/07/2023
A19: SB0015 | B19: BP-C0020 | C19: Mr Adebowale Oluwapelumi Joseph | D19: Land | E19: Green City Phase 1 (Lantaba, Ketu-Epe) | F19: 600sqm | G19: 45161 | H19: =IF(G19="","",YEAR(G19)) | I19: 3600000 | J19: 3600000 | K19: =IF(OR(I19="",J19=""),"",I19-J19) | L19: 3 months | M19: Bought | N19: BLOCK C3 | O19: Collected by client sister | P19: MD | Q19: BAAY PROJECTS CLIENTS > GREEN CITY KETU 1 INVESTORS LIS | R19: 13 | S19: 23/08/2023
A20: SB0016 | B20: BP-C0021 | C20: Mr Oyewole Sheriff Oyewusi | D20: Land | E20: Green City Phase 1 (Lantaba, Ketu-Epe) | F20: 600sqm | G20: 45161 | H20: =IF(G20="","",YEAR(G20)) | I20: 3600000 | J20: 3600000 | K20: =IF(OR(I20="",J20=""),"",I20-J20) | L20: 3 months | M20: Bought | N20: BLOCK C6 | O20: Yet to collect Physical Document | P20: Ms Bolanle | Q20: BAAY PROJECTS CLIENTS > GREEN CITY KETU 1 INVESTORS LIS | R20: 12 | S20: 23/08/2023
A21: SB0017 | B21: BP-C0022 | C21: Mr Folaranmi Olatunde | D21: Land | E21: Green City Phase 1 (Lantaba, Ketu-Epe) | F21: 600sqm | G21: 45162 | H21: =IF(G21="","",YEAR(G21)) | I21: 1500000 | J21: 1500000 | K21: =IF(OR(I21="",J21=""),"",I21-J21) | L21: 3 months | M21: Bought | N21: BLOCK E2 | O21: Collected by Client representative | P21: MD | Q21: BAAY PROJECTS CLIENTS > GREEN CITY KETU 1 INVESTORS LIS | R21: 11 | S21: 24/08/2023
A22: SB0018 | B22: BP-C0023 | C22: MR KOREDE ADESE | D22: Land | E22: Green City Phase 1 (Lantaba, Ketu-Epe) | F22: 250sqm | G22: 45166 | H22: =IF(G22="","",YEAR(G22)) | I22: 3000000 | J22: 3000000 | K22: =IF(OR(I22="",J22=""),"",I22-J22) | L22: 3months | M22: Bought | N22: BLOCK D6b | O22: Physical Document Collected | P22: MD | Q22: BAAY PROJECTS CLIENTS > GREEN CITY KETU 1 INVESTORS LIS | R22: 6 | S22: 28/8/2023
A23: SB0019 | B23: BP-C0024 | C23: Ms Peace Ikpotokin | D23: Land | E23: Green City Phase 1 (Lantaba, Ketu-Epe) | F23: 600sqm | G23: 45166 | H23: =IF(G23="","",YEAR(G23)) | I23: 3600000 | J23: 50000 | K23: =IF(OR(I23="",J23=""),"",I23-J23) | L23: 6months | M23: Promise | N23: NIL | O23: Initial deposit | P23: MD | Q23: BAAY PROJECTS CLIENTS > GREEN CITY KETU 1 INVESTORS LIS | R23: 14 | S23: 28/08/2023
A24: SB0020 | B24: BP-C0025 | C24: Mrs Obadara Dorcas Adebisi | D24: Land | E24: Green City Phase 1 (Lantaba, Ketu-Epe) | F24: 250sqm | G24: 45173 | H24: =IF(G24="","",YEAR(G24)) | I24: 4320000 | J24: 4320000 | K24: =IF(OR(I24="",J24=""),"",I24-J24) | L24: 3 months | M24: Bought | N24: BLOCK D4A | O24: Collected by Client | P24: Barister Nelson | Q24: BAAY PROJECTS CLIENTS > GREEN CITY KETU 1 INVESTORS LIS | R24: 15 | S24: 2023-04-09
A25: SB0021 | B25: BP-C0027 | C25: Mr Edun Ayobami Simeon and bro | D25: Land | E25: Green City Phase 1 (Lantaba, Ketu-Epe) | F25: 2 units of 600sqm | G25: 45190 | H25: =IF(G25="","",YEAR(G25)) | I25: 1500000 | J25: 1500000 | K25: =IF(OR(I25="",J25=""),"",I25-J25) | L25: 12 months | M25: Bought | N25: BLOCK F2345 | O25: Collected by client | P25: Mr Olaiya/MD | Q25: BAAY PROJECTS CLIENTS > GREEN CITY KETU 1 INVESTORS LIS | R25: 16 | S25: 21/09/2023
A26: SB0022 | B26: BP-C0026 | C26: Mr & Mrs Adebayo Dada | D26: Land | E26: Green City Phase 1 (Lantaba, Ketu-Epe) | F26: 500sqm | G26: 45205 | H26: =IF(G26="","",YEAR(G26)) | I26: 8400000 | J26: 8400000 | K26: =IF(OR(I26="",J26=""),"",I26-J26) | L26: 3months | M26: Bought | N26: BLOCK D2 | O26: Collected by Client's Brother | P26: Mrs Abimbola | Q26: BAAY PROJECTS CLIENTS > GREEN CITY KETU 1 INVESTORS LIS | R26: 17 | S26: 2023-06-10
A27: SB0023 | B27: BP-C0031 | C27: Mr Eguavoen Harrison | D27: Land | E27: Green City Agbowa | F27: 250sqm | G27: 45209 | H27: =IF(G27="","",YEAR(G27)) | I27: 750000 | J27: 750000 | K27: =IF(OR(I27="",J27=""),"",I27-J27) | L27: 3months | M27: Refund | P27: Ms Blessing | Q27: BAAY PROJECTS CLIENTS > GREENCITY AGBOWA | R27: 2 | S27: 2023-10-10
A28: SB0024 | B28: BP-C0032 | C28: Mr Tomiwa Ibiks ********* | D28: Land | E28: Green City Phase 1 (Lantaba, Ketu-Epe) | F28: 600sqm | G28: 45209 | H28: =IF(G28="","",YEAR(G28)) | I28: 3600000 | J28: 1000000 | K28: =IF(OR(I28="",J28=""),"",I28-J28) | L28: 3months | M28: Paying | N28: Not Allocated Yet | O28: Not yet submitted subscription form | P28: MD | Q28: BAAY PROJECTS CLIENTS > GREEN CITY KETU 1 INVESTORS LIS | R28: 24 | S28: 2023-10-10
A29: SB0025 | B29: BP-C0033 | C29: Mr Olumoko Oladapo Oluwaseun | D29: Land | E29: Green City Phase 1 (Lantaba, Ketu-Epe) | F29: 500sqm | G29: 45211 | H29: =IF(G29="","",YEAR(G29)) | I29: 6000000 | J29: 6000000 | K29: =IF(OR(I29="",J29=""),"",I29-J29) | L29: 3months | M29: Bought | N29: BLOCK C4 | O29: Not yet Collected | P29: Ms Bolanle | Q29: BAAY PROJECTS CLIENTS > GREEN CITY KETU 1 INVESTORS LIS + Foreshore financials sheet | R29: 21 | S29: 2023-12-10
A30: SB0026 | B30: BP-C0034 | C30: Mrs Ndubuisi Ujunwa | D30: Land | E30: Green City Phase 1 (Lantaba, Ketu-Epe) | F30: 250sqm | G30: 45211 | H30: =IF(G30="","",YEAR(G30)) | I30: 3900000 | J30: 3900000 | K30: =IF(OR(I30="",J30=""),"",I30-J30) | L30: 3 Months | M30: Bought | N30: BLOCK D3A | O30: Collected by Client | P30: Ms Immaculate | Q30: BAAY PROJECTS CLIENTS > GREEN CITY KETU 1 INVESTORS LIS | R30: 22 | S30: 2023-12-10
A31: SB0027 | B31: BP-C0035 | C31: Vacant | D31: Land | E31: Green City Phase 1 (Lantaba, Ketu-Epe) | F31: 600sqm | G31: 45211 | H31: =IF(G31="","",YEAR(G31)) | I31: 1500000 | J31: 1500000 | K31: =IF(OR(I31="",J31=""),"",I31-J31) | L31: 3months | M31: bought | N31: BLOCK C2 | O31: Yet to collect Physical Document | P31: MD | Q31: BAAY PROJECTS CLIENTS > GREEN CITY KETU 1 INVESTORS LIS | R31: 23 | S31: 2023-12-10
A32: SB0028 | B32: BP-C0037 | C32: Miss Okezie Mandy Ifeoma | D32: Land | E32: Green City Phase 1 (Lantaba, Ketu-Epe) | F32: 250sqm | G32: 45228 | H32: =IF(G32="","",YEAR(G32)) | I32: 4600000 | J32: 4600000 | K32: =IF(OR(I32="",J32=""),"",I32-J32) | L32: 3 Months | M32: Bought | N32: BLOCK D3B | O32: Collected by Client | P32: Celina | Q32: BAAY PROJECTS CLIENTS > GREEN CITY KETU 1 INVESTORS LIS | R32: 25 | S32: 29/10/2023
A33: SB0029 | B33: BP-C0040 | C33: Bassey Christopher | D33: Land | E33: Green City Phase 1 (Lantaba, Ketu-Epe) | F33: 1000sqm & 600sqm | G33: 45229 | H33: =IF(G33="","",YEAR(G33)) | I33: 2000000 | J33: 2000000 | K33: =IF(OR(I33="",J33=""),"",I33-J33) | L33: 3 Months | M33: Bought | N33: BLOCK A45 | O33: Collected by Client | P33: Ms Immaculate | Q33: BAAY PROJECTS CLIENTS > GREEN CITY KETU 1 INVESTORS LIS | R33: 26 | S33: 30/10/2023
A34: SB0030 | B34: BP-C0029 | C34: Mr Ohanehi Anthony Chukwunonso | D34: Land | E34: Green City Phase 1 (Lantaba, Ketu-Epe) | F34: 600sqm Commercial | G34: 45229 | H34: =IF(G34="","",YEAR(G34)) | I34: 3000000 | J34: 9540000 | K34: =IF(OR(I34="",J34=""),"",I34-J34) | L34: 6 Months | M34: Bought | N34: BLOCK A678 | O34: Collected by Client | P34: Ms Immaculate | Q34: BAAY PROJECTS CLIENTS > GREEN CITY KETU 1 INVESTORS LIS + Foreshore financials sheet | R34: 19 | S34: 2023-10-30
A35: SB0031 | B35: BP-C0036 | C35: Ohumende Paul Osaze | D35: Land | E35: Green City Phase 1 (Lantaba, Ketu-Epe) | F35: 600sqm (6 Units) | G35: 45232 | H35: =IF(G35="","",YEAR(G35)) | I35: 15000000 | J35: 15000000 | K35: =IF(OR(I35="",J35=""),"",I35-J35) | L35: 3 months | M35: Bought | N35: BLOCK H123456 | O35: Collected by Client | P35: MD | Q35: BAAY PROJECTS CLIENTS > GREEN CITY KETU 1 INVESTORS LIS | R35: 27 | S35: 2023-02-11
A36: SB0032 | B36: BP-C0041 | C36: Alhaji Badamasi Mohammadu | D36: Land | E36: Green City Phase 1 (Lantaba, Ketu-Epe) | F36: 500sqm | G36: 45233 | H36: =IF(G36="","",YEAR(G36)) | I36: 27600000 | J36: 27600000 | K36: =IF(OR(I36="",J36=""),"",I36-J36) | L36: 3 months | M36: Bought | N36: BLOCK G1 | O36: Collected by Client | P36: Ms Tobi Associate | Q36: BAAY PROJECTS CLIENTS > GREEN CITY KETU 1 INVESTORS LIS | R36: 28 | S36: 2023-03-11
